2022-11-09 15:04:31,572 - root - ERROR - Traceback (most recent call last):
  File "C:\Users\rfranqui\OneDrive - Entegris\Documents\P\Projects\RabbitMQ\send.py", line 267, in main
    connection.close()
  File "C:\Users\rfranqui\Miniconda3\lib\site-packages\pika\adapters\blocking_connection.py", line 809, in close
    channel.close(reply_code, reply_text)
  File "C:\Users\rfranqui\Miniconda3\lib\site-packages\pika\adapters\blocking_connection.py", line 1539, in close
    self._flush_output(lambda: self.is_closed)
  File "C:\Users\rfranqui\Miniconda3\lib\site-packages\pika\adapters\blocking_connection.py", line 1353, in _flush_output
    self._connection._flush_output(lambda: self.is_closed, *waiters)
  File "C:\Users\rfranqui\Miniconda3\lib\site-packages\pika\adapters\blocking_connection.py", line 523, in _flush_output
    raise self._closed_result.value.error
pika.exceptions.ConnectionClosedByBroker: (320, "CONNECTION_FORCED - broker forced connection closure with reason 'shutdown'")

