2022-11-09 15:13:44,209 - root - INFO - No new files will check in 5 seconds
2022-11-09 15:13:49,230 - root - INFO - No new files will check in 5 seconds
2022-11-09 15:13:54,235 - root - INFO - No new files will check in 5 seconds
2022-11-09 15:13:59,247 - root - INFO - No new files will check in 5 seconds
2022-11-09 15:14:04,276 - root - DEBUG - Connection active
2022-11-09 15:14:04,291 - root - INFO - Moved \ag.txt' to long term storage
2022-11-09 15:14:04,308 - root - DEBUG - Connection active
2022-11-09 15:14:04,329 - root - INFO - Moved \CMC_Q02_0MATERIAL_ATTR.csv' to long term storage
2022-11-09 15:14:04,399 - root - DEBUG - Connection active
2022-11-09 15:14:04,415 - root - INFO - Moved \CMC_Q02_0PLANT_ATTR.csv' to long term storage
2022-11-09 15:14:04,432 - root - DEBUG - Connection active
2022-11-09 15:14:04,451 - root - INFO - Moved \CMC_Q02_0PROD_HIER_TEXT.csv' to long term storage
2022-11-09 15:14:04,506 - root - DEBUG - Connection active
2022-11-09 15:14:04,712 - root - INFO - Moved \CMC_Q02_MARM.csv' to long term storage
2022-11-09 15:14:12,014 - root - ERROR - Connection to RabbitMQ lost, check that RabbitMQ instance is still working
2022-11-09 15:14:12,016 - root - ERROR - Traceback (most recent call last):
  File "C:\Users\rfranqui\OneDrive - Entegris\Documents\P\Projects\RabbitMQ\send.py", line 268, in main
    connection.close()
  File "C:\Users\rfranqui\Miniconda3\lib\site-packages\pika\adapters\blocking_connection.py", line 809, in close
    channel.close(reply_code, reply_text)
  File "C:\Users\rfranqui\Miniconda3\lib\site-packages\pika\adapters\blocking_connection.py", line 1539, in close
    self._flush_output(lambda: self.is_closed)
  File "C:\Users\rfranqui\Miniconda3\lib\site-packages\pika\adapters\blocking_connection.py", line 1353, in _flush_output
    self._connection._flush_output(lambda: self.is_closed, *waiters)
  File "C:\Users\rfranqui\Miniconda3\lib\site-packages\pika\adapters\blocking_connection.py", line 523, in _flush_output
    raise self._closed_result.value.error
pika.exceptions.ConnectionClosedByBroker: (320, "CONNECTION_FORCED - broker forced connection closure with reason 'shutdown'")

2022-11-09 15:14:12,017 - root - INFO - Will Attempt Reconection in 5 seconds
2022-11-09 15:14:21,123 - root - ERROR - Connection check failed, sleeping 5 seconds
2022-11-09 15:14:26,129 - root - ERROR - Fatal Error
2022-11-09 15:14:26,130 - root - ERROR - Traceback (most recent call last):
  File "C:\Users\rfranqui\OneDrive - Entegris\Documents\P\Projects\RabbitMQ\send.py", line 250, in main
    if checkConnection() == True:
  File "C:\Users\rfranqui\OneDrive - Entegris\Documents\P\Projects\RabbitMQ\send.py", line 124, in checkConnection
    return connect_open
UnboundLocalError: local variable 'connect_open' referenced before assignment

2022-11-09 15:14:26,130 - root - INFO - Will Attempt Reconection in 5 seconds
2022-11-09 15:14:35,248 - root - ERROR - Connection check failed, sleeping 5 seconds
2022-11-09 15:14:40,263 - root - ERROR - Fatal Error
2022-11-09 15:14:40,264 - root - ERROR - Traceback (most recent call last):
  File "C:\Users\rfranqui\OneDrive - Entegris\Documents\P\Projects\RabbitMQ\send.py", line 250, in main
    if checkConnection() == True:
  File "C:\Users\rfranqui\OneDrive - Entegris\Documents\P\Projects\RabbitMQ\send.py", line 124, in checkConnection
    return connect_open
UnboundLocalError: local variable 'connect_open' referenced before assignment

2022-11-09 15:14:40,265 - root - INFO - Will Attempt Reconection in 5 seconds
